Traceback (most recent call last):
  File "/home/runner/micromamba-root/envs/buildenv/lib/python3.10/site-packages/jupyter_cache/executors/utils.py", line 51, in single_nb_execution
    executenb(
  File "/home/runner/micromamba-root/envs/buildenv/lib/python3.10/site-packages/nbclient/client.py", line 1204, in execute
    return NotebookClient(nb=nb, resources=resources, km=km, **kwargs).execute()
  File "/home/runner/micromamba-root/envs/buildenv/lib/python3.10/site-packages/nbclient/util.py", line 84, in wrapped
    return just_run(coro(*args, **kwargs))
  File "/home/runner/micromamba-root/envs/buildenv/lib/python3.10/site-packages/nbclient/util.py", line 62, in just_run
    return loop.run_until_complete(coro)
  File "/home/runner/micromamba-root/envs/buildenv/lib/python3.10/asyncio/base_events.py", line 646, in run_until_complete
    return future.result()
  File "/home/runner/micromamba-root/envs/buildenv/lib/python3.10/site-packages/nbclient/client.py", line 663, in async_execute
    await self.async_execute_cell(
  File "/home/runner/micromamba-root/envs/buildenv/lib/python3.10/site-packages/nbclient/client.py", line 965, in async_execute_cell
    await self._check_raise_for_error(cell, cell_index, exec_reply)
  File "/home/runner/micromamba-root/envs/buildenv/lib/python3.10/site-packages/nbclient/client.py", line 862, in _check_raise_for_error
    raise CellExecutionError.from_cell_and_msg(cell, exec_reply_content)
nbclient.exceptions.CellExecutionError: An error occurred while executing the following cell:
------------------
import numpy as np

# Generate a range of t from 0 to 2, with a timestep of 0.5
t = np.arange(0,2.1,.01)

# Use or ne function
y = euler_integrate(yprime, 
                    t=t, 
                    y0=1)

#Plot the results
plt.plot(t,y,'ok', label='Numerical Sol''n to dy/dt=-y, y(t=0)=1')
plt.xlabel('t')
plt.ylabel('Numerical Sol''n to dy/dt=-y, y(t=0)=1')

t=np.linspace(0,2,100)

plt.plot(t,np.exp(-t),'k-', label='full solution, $e^{-t}$')
plt.legend()
plt.xlabel('t')
plt.ylabel('y')
------------------

[0;31m---------------------------------------------------------------------------[0m
[0;31mNameError[0m                                 Traceback (most recent call last)
Cell [0;32mIn [3], line 12[0m
[1;32m      7[0m y [38;5;241m=[39m euler_integrate(yprime, 
[1;32m      8[0m                     t[38;5;241m=[39mt, 
[1;32m      9[0m                     y0[38;5;241m=[39m[38;5;241m1[39m)
[1;32m     11[0m [38;5;66;03m#Plot the results[39;00m
[0;32m---> 12[0m [43mplt[49m[38;5;241m.[39mplot(t,y,[38;5;124m'[39m[38;5;124mok[39m[38;5;124m'[39m, label[38;5;241m=[39m[38;5;124m'[39m[38;5;124mNumerical Sol[39m[38;5;124m'[39m[38;5;124m'[39m[38;5;124mn to dy/dt=-y, y(t=0)=1[39m[38;5;124m'[39m)
[1;32m     13[0m plt[38;5;241m.[39mxlabel([38;5;124m'[39m[38;5;124mt[39m[38;5;124m'[39m)
[1;32m     14[0m plt[38;5;241m.[39mylabel([38;5;124m'[39m[38;5;124mNumerical Sol[39m[38;5;124m'[39m[38;5;124m'[39m[38;5;124mn to dy/dt=-y, y(t=0)=1[39m[38;5;124m'[39m)

[0;31mNameError[0m: name 'plt' is not defined
NameError: name 'plt' is not defined

